Workbook

Sheet Export Summary
B3: This document was exported from Numbers. Each table was converted to an Excel worksheet. All other objects on each Numbers sheet were placed on separate worksheets. Please be aware that formula calculations may differ in Excel.
B7: Numbers Sheet Name | C7: Numbers Table Name | D7: Excel Worksheet Name
B9: README
C10: Table 1 | D10: README
B11: Weights & Rules
C12: Table 1 | D12: Weights & Rules
B13: Calculation Guide
C14: Table 1 | D14: Calculation Guide
B15: L1 Asset Classes
C16: Table 1 | D16: L1 Asset Classes
B17: Equity Segments
C18: Table 1 | D18: Equity Segments
B19: Debt Buckets
C20: Table 1 | D20: Debt Buckets
B21: Precious Metals
C22: Table 1 | D22: Precious Metals
B23: Sector Satellite
C24: Table 1 | D24: Sector Satellite
B25: Portfolio Rollup
C26: Table 1 | D26: Portfolio Rollup
B27: Data Trackers
C28: Table 1 | D28: Data Trackers
B29: Monitoring & Review
C30: Table 1 | D30: Monitoring & Review

Sheet README
B2: Multi-Asset Allocation Framework — Equity, Debt, Precious Metals & Sector Satellite
B4: Architecture: two levels plus a caged satellite
B5: LEVEL 1 decides the split between Equity, Debt and Precious Metals. LEVEL 2 allocates within each: equity across Large/Mid/Small/International, debt across duration-credit buckets, metals between gold and silver. The SECTOR SATELLITE is a capped sleeve carved out of equity, deployed only when sectors clear a high bar — empty by default. The Portfolio Rollup multiplies the levels into one final allocation summing to 100%.
B7: Workflow
B8: Step 1 — Log monthly data on Data Trackers (index P/E, flows, 10Y yield, credit spread, gold and gold/silver ratio). Percentiles build automatically as history accumulates.
B9: Step 2 — At reviews, enter attractiveness percentiles (0–100, higher = more attractive FORWARD) on the scoring sheets. Valuation and flow percentiles must be INVERTED from raw history percentiles (expensive/euphoric = low attractiveness). Yield percentiles for debt are NOT inverted — high yields vs history = attractive carry.
B10: Step 3 — Set veto flags where triggered. Vetoes block overweights only; they never force underweights.
B11: Step 4 — Read Portfolio Rollup for the final allocation. Implement changes gradually over 4–8 weeks.
B13: Design principles
B14: Neutral weights are policy — set from your risk profile, changed at most annually, never by this framework. Tilts are capped (lean, never lurch). Slow signals (valuation, carry, cycle) drive; flows and momentum only nudge. Sectors are guilty until proven innocent: the satellite stays empty unless a sector clears the qualification threshold, and the sleeve is hard-capped because sector timing has the worst base rates of everything in this workbook.
B16: Color coding
B17: Blue = inputs. Black = formulas. Yellow = key assumptions. Green = cross-sheet references.
B18: Data sources: NSE index valuations; AMFI category flows; RBI/CCIL for G-sec yields; FIMMDA/broker reports for AAA spreads; gold price and gold/silver ratio from any bullion data source; US real yields from FRED. This is a decision-support framework, not investment advice — backtest weights against your historical MF data before trusting them.

Sheet Weights & Rules
A1: Weights & Rules
A3: Level 1 — Asset class signal weights (uniform signals, class-specific guidance)
A4: Signal | B4: Weight | C4: Guidance
A5: Valuation / carry attractiveness | B5: 0.3 | C5: Equity: earnings yield vs 10Y G-sec, index P/E percentile (inverted). Debt: real yield & absolute yield percentile (NOT inverted — high yield = attractive). Metals: real gold price vs history (inverted).
A6: Macro / cycle support | B6: 0.2 | C6: Rate cycle direction (cuts favour equity duration & long debt & gold), growth momentum vs expectations, inflation trajectory.
A7: Fundamentals | B7: 0.2 | C7: Equity: earnings revision breadth. Debt: credit conditions, fiscal supply of paper. Metals: central-bank buying, ETF holdings trend.
A8: Flows & sentiment (contrarian) | B8: 0.15 | C8: Category flows vs history, INVERTED: euphoric inflows = low score.
A9: Momentum (12M relative) | B9: 0.15 | C9: Scored as-is: persistent relative strength = modestly positive.
A10: Total (must equal 100%) | B10: =SUM(B5:B9) -> 1
A12: Level 2 — Equity segment signal weights
A13: Signal | B13: Weight | C13: Guidance
A14: Valuation vs own history | B14: 0.3 | C14: Segment P/E-P/B percentile vs 10–15Y history, inverted. International: S&P 500 fwd P/E and India–US gap.
A15: Relative value vs other segments | B15: 0.2 | C15: Mid–Large / Small–Large spread percentiles (Data Trackers), inverted. For Large Cap: wide spreads = high score.
A16: Earnings revision breadth | B16: 0.2 | C16: Upgrade/downgrade ratio vs history.
A17: Earnings growth differential | B17: 0.15 | C17: Segment consensus EPS growth vs Large Cap. International: US vs India growth + INR trend.
A18: Margin / cycle position | B18: 0.15 | C18: Aggregate margins vs history; credit growth, capacity utilization for domestic mid/small.
A19: Total (must equal 100%) | B19: =SUM(B14:B18) -> 1
A21: Level 2 — Debt bucket signal weights
A22: Signal | B22: Weight | C22: Guidance
A23: Carry vs history (YTM percentile) | B23: 0.3 | C23: Bucket YTM vs own history — NOT inverted: high yield percentile = attractive.
A24: Rate-cycle duration benefit | B24: 0.3 | C24: Expected rate direction × bucket duration: cuts ahead = long/gilt scores high; hikes = short scores high.
A25: Credit spread cushion | B25: 0.25 | C25: AAA/corporate spread percentile vs history: wide spreads = attractive for corporate bucket, score high; tight = low.
A26: Liquidity / redemption safety | B26: 0.15 | C26: Category AUM depth and stress behaviour; liquid/short structurally higher.
A27: Total (must equal 100%) | B27: =SUM(B23:B26) -> 1
A29: Level 2 — Precious metals split signal weights
A30: Signal | B30: Weight | C30: Guidance
A31: Gold/Silver ratio positioning | B31: 0.4 | C31: Ratio percentile vs 20Y history: very high ratio = silver cheap vs gold (silver scores high, gold low); very low = reverse.
A32: Real-rates trend benefit | B32: 0.35 | C32: Falling US real yields favour both, gold most — score gold higher when real yields rolling over.
A33: Industrial demand cycle | B33: 0.25 | C33: Silver-specific: global manufacturing/solar cycle; gold scores neutral (50) here.
A34: Total (must equal 100%) | B34: =SUM(B31:B33) -> 1
A36: Sector satellite signal weights
A37: Signal | B37: Weight | C37: Guidance
A38: Valuation vs own history | B38: 0.3 | C38: Sector index P/E-P/B percentile vs 10Y+ history, inverted.
A39: Earnings revisions & momentum | B39: 0.3 | C39: Upgrade breadth and delivery vs estimates — the engine of sector rotation.
A40: Relative price momentum (6–12M) | B40: 0.25 | C40: Vs Nifty; scored as-is.
A41: Cycle position | B41: 0.15 | C41: Where the sector's own cycle sits (credit cycle for banks, capex for industrials, generic/deal cycle for IT/pharma).
A42: Total (must equal 100%) | B42: =SUM(B38:B41) -> 1
A44: Tilt parameters & caps
A45: Parameter | B45: Value | C45: Guidance
A46: Max tilt — Level 1 asset classes | B46: 0.2 | C46: Asset-class moves are the biggest risk decisions; tightest cap.
...

Sheet Calculation Guide
A1: Calculation Guide — exactly how to compute every score
A3: THE UNIVERSAL RECIPE (memorize this; everything below is a variation of it): (1) Get the raw metric's monthly history — the longer the better, 10Y+ ideal. (2) Compute the current value's percentile within that history: =PERCENTRANK(history_range, current_value)*100. (3) Convert percentile to ATTRACTIVENESS: if the metric is a PRICE/VALUATION/FLOW (high = expensive/euphoric), attractiveness = 100 − percentile. If the metric is a YIELD/SPREAD-CUSHION/BREADTH/MOMENTUM (high = good), attractiveness = percentile as-is. (4) Where history isn't available, use the stated rubric (a lookup table from observable conditions to a score). Enter the resulting 0–100 number in the blue cell. When a signal has two sub-parts, average them.
A5: L1 ASSET CLASSES — Equity column
A6: Signal | B6: Exact calculation — step by step | C6: Data source | D6: Worked example
A7: Valuation / carry | B7: Two parts, then average. (a) Earnings-yield gap = (100 / Nifty 50 trailing P/E) − 10Y G-sec yield. Build monthly history of this gap; attractiveness = PERCENTRANK of current gap × 100, AS-IS (high gap = equity cheap vs bonds = attractive). (b) Nifty P/E percentile vs its own 10–15Y history, INVERTED: attractiveness = 100 − percentile. Final score = (a + b) / 2. | C7: NSE index P/E (niftyindices.com); 10Y yield from Data Trackers rates log | D7: Nifty P/E 22 → earnings yield 4.55%; 10Y = 6.75% → gap = −2.2%. If that gap sits at the 30th %ile of history → (a)=30. P/E 22 = 55th %ile of history → (b) = 100−55 = 45. Score = (30+45)/2 ≈ 38.
A8: Macro / cycle support | B8: Rubric (no history needed). Start at 50. RBI cutting or clearly about to cut: +20. On hold, neutral stance: +0. Hiking or hawkish: −20. GDP/high-frequency growth beating expectations: +10; missing: −10. Inflation falling toward target: +5; rising: −5. Clamp 0–100. | C8: RBI policy statements; monthly PMI/GST/IIP prints vs consensus | D8: RBI cut once, more expected (+20), growth in line (0), CPI easing (+5) → 50+25 = 75.
A9: Fundamentals | B9: Earnings revision breadth = upgrades ÷ (upgrades + downgrades) for Nifty 100 constituents, monthly. Attractiveness = PERCENTRANK of current breadth vs 5Y+ history × 100, AS-IS. If you can't source breadth, substitute: % change in Nifty consensus FY+1 EPS over the last 3 months, percentiled the same way. | C9: Brokerage strategy reports (most publish revision breadth monthly); ACE Equity/Bloomberg if available | D9: Breadth = 0.48 (48% of changes are upgrades); history percentile = 60 → score 60.
A10: Flows & sentiment (contrarian) | B10: 3-month average of total ACTIVE equity fund net flows (AMFI) as % of equity AUM. Percentile vs history, then INVERT: attractiveness = 100 − percentile. Euphoric inflows = low score. | C10: AMFI monthly data (flows and AUM by category) | D10: 3M avg flows at 85th %ile of history → score = 100−85 = 15 (crowd is all-in → unattractive).
A11: Momentum (12M relative) | B11: Nifty 50 total-return 12M % minus 10Y G-sec yield (i.e., equity excess return). Percentile vs history, AS-IS. | C11: Index TR from NSE; yield from your rates log | D11: Nifty 12M TR = 14%, yield 6.75% → excess 7.25% → 55th %ile → score 55.
A12: L1 — Debt column
A13: Signal | B13: Exact calculation — step by step | C13: Data source | D13: Worked example
A14: Valuation / carry | B14: Real 10Y yield = 10Y G-sec yield − latest CPI YoY. Percentile vs 10Y+ history, AS-IS (high real yield = attractive). Do NOT invert. | C14: Rates log (10Y); MOSPI CPI print | D14: 10Y = 6.75%, CPI = 4.0% → real yield 2.75% → 78th %ile of history → score 78.
A15: Macro / cycle support | B15: Rubric, start at 50: cuts expected over next 12M: +20 (duration gains ahead). On hold: 0. Hiking cycle: −15. Heavy G-sec supply / fiscal slippage risk: −10. Inflation trending below target: +10. | C15: RBI guidance, budget documents, bond-desk commentary | D15: Cuts expected (+20), supply normal (0), inflation at target (+0) → 70.
A16: Fundamentals | B16: Credit conditions rubric, start at 50: corporate downgrade/default cycle quiet: +10; rising downgrades or a visible credit event: −25; banking system liquidity comfortably in surplus: +10; deficit/tight: −10. | C16: CRISIL/ICRA rating action summaries (quarterly); RBI liquidity data | D16: Quiet credit cycle (+10), surplus liquidity (+10) → 70.
A17: Flows & sentiment (contrarian) | B17: 3M avg net flows into duration categories (corporate bond + gilt + medium/long funds, AMFI) as % of their AUM. Percentile vs history, INVERTED. | C17: AMFI | D17: Duration-fund flows at 40th %ile → score = 60.
A18: Momentum (12M relative) | B18: CRISIL/NIFTY composite bond index 12M return, percentile vs history, AS-IS. | C18: Index providers / any debt fund factsheet quotes the index | D18: Bond index 12M = 8.2% → 65th %ile → 65.
A19: L1 — Precious Metals column
A20: Signal | B20: Exact calculation — step by step | C20: Data source | D20: Worked example
A21: Valuation / carry | B21: INR gold price deflated by CPI index (real gold price). Percentile vs 15–20Y history, INVERTED: attractiveness = 100 − percentile. | C21: Metals log (gold ₹/10g); CPI index | D21: Real gold price at 90th %ile of 20Y history → score = 10 (historically expensive).
A22: Macro / cycle support | B22: US 10Y real yield (TIPS), 6M change rubric: fallen >50bp: 75. Fallen 10–50bp: 60. Flat ±10bp: 50. Risen 10–50bp: 40. Risen >50bp: 25. (Falling real yields are gold's main macro driver.) | C22: FRED series DFII10 (free) | D22: TIPS yield −30bp over 6M → 60.
A23: Fundamentals | B23: Rubric, start 50: central-bank buying running above 5Y average: +15; below: −10. Global gold ETF holdings rising 3M: +10; falling: −10. | C23: World Gold Council quarterly demand report (free) | D23: CB buying strong (+15), ETF holdings flat (0) → 65.
A24: Flows & sentiment (contrarian) | B24: Indian gold ETF net flows (AMFI), 3M avg, percentile vs history, INVERTED. | C24: AMFI (gold ETF category, already in your flow log) | D24: Gold ETF flows at 88th %ile → score 12 — also check the parabolic-move veto.
A25: Momentum (12M relative) | B25: Gold INR 12M return percentile vs history, AS-IS — but if return >40% in 6M the parabolic veto fires regardless of this score. | C25: Metals log (the tracker computes 12M return %ile once seeded) | D25: 12M return 28% → 92nd %ile → score 92, but check veto.
A26: EQUITY SEGMENTS (per segment: Large / Mid / Small / International)
A27: Signal | B27: Exact calculation — step by step | C27: Data source | D27: Worked example
A28: Valuation vs own history | B28: Segment index trailing P/E percentile vs its own 10–15Y monthly history, INVERTED: attractiveness = 100 − PERCENTRANK×100. Optionally average with the same on P/B. International: use S&P 500 forward P/E vs its own history, inverted; then subtract 5–10 points if the India–US valuation gap is at an extreme favouring India, add if favouring US. | C28: niftyindices.com historical P/E (downloadable); multpl.com or broker data for S&P fwd P/E | D28: Midcap 150 P/E at 82nd %ile of its history → score = 18.
A29: Relative value vs segments | B29: Directly from Data Trackers: Mid Spread %ile and Small Spread %ile columns compute automatically. Mid Cap score = 100 − Mid Spread %ile. Small Cap score = 100 − Small Spread %ile. Large Cap score = average of the two raw spread %iles AS-IS (wide spreads favour large). International = 100 − percentile of (S&P fwd P/E − Nifty fwd P/E) spread vs history. | C29: Data Trackers valuation log (auto once seeded) | D29: Mid–Large spread at 75th %ile → Mid score 25; Large score ≈ (75+80)/2 = 77 if Small spread is 80th %ile.
A30: Earnings revision breadth | B30: Same construction as L1 but per segment universe (Nifty 100 / Midcap 150 / Smallcap 250 constituents). Percentile vs history, AS-IS. If per-segment breadth is unobtainable, use 3M change in the segment index consensus EPS. | C30: Brokerage midcap/smallcap strategy notes publish this; else EPS trend from index factsheets | D30: Smallcap breadth at 45th %ile → 45.
A31: Earnings growth differential | B31: Segment consensus FY+1 EPS growth minus Large Cap's. Rubric: gap ≥ +8pp: 75. +3 to +8: 60. −3 to +3: 50. −3 to −8: 40. Below −8: 25. Large Cap itself is always 50. International: US EPS growth minus India's, same rubric, PLUS 5 points structural INR-depreciation tailwind. | C31: Index consensus estimates from broker strategy reports | D31: Midcap growth 18% vs Largecap 12% → gap +6pp → 60.
A32: Margin / cycle position | B32: Segment aggregate EBITDA margin percentile vs own history, INVERTED (peak margins = mean-reversion risk), averaged with a cycle rubric: credit growth accelerating +10, capacity utilization >75% +5 (both favour domestic mid/small), else 0/negative. International: use US margin percentile inverted. | C32: Broker aggregate-margin charts; RBI OBICUS for capacity utilization | D32: Small cap margins at 85th %ile → 15; credit accelerating +10 → (15+60)/2 ≈ 38 (rubric half scored 50+10).
A33: DEBT BUCKETS (Liquid/Short · Corporate/Medium · Gilt/Long)
A34: Signal | B34: Exact calculation — step by step | C34: Data source | D34: Worked example
A35: Carry vs history (YTM %ile) | B35: Use each bucket's representative category average YTM (from 3–4 large funds' factsheets): Liquid/Short → short-duration category; Corporate → corporate bond category; Gilt → gilt/long category. Percentile vs the history you accumulate, AS-IS — high yield = attractive. Until history builds, proxy: Liquid = 1Y T-bill %ile, Corporate = 3Y AAA %ile, Gilt = 10Y G-sec %ile (rates log). | C35: Fund factsheets (monthly YTM disclosure); rates log for proxies | D35: 10Y at 70th %ile of history → Gilt carry score 70.
A36: Rate-cycle duration benefit | B36: Pure rubric on expected RBI path over 12M: Cuts >50bp expected → Gilt 80 / Corporate 60 / Liquid 30. Cuts 25–50bp → 70/58/40. On hold → 50/50/55. Hikes 25–50bp → 30/40/70. Hikes >50bp → 20/35/80. | C36: RBI guidance, OIS-implied expectations from bond commentary | D36: Market pricing ~50bp cuts → Gilt 70–80, Liquid 30–40.
A37: Credit spread cushion | B37: AAA Spread %ile from the rates log (auto). Corporate bucket score = spread %ile AS-IS (wide = paid to take credit). Liquid and Gilt score fixed 50 on this signal (not their driver). | C37: Data Trackers rates log | D37: AAA spread 65bp = 40th %ile → Corporate scores 40 (tight-ish spreads).
A38: Liquidity / redemption safety | B38: Standing structural rubric, adjusted only in stress: Liquid/Short = 90. Corporate = 65 (drop to 40 if any credit-fund stress episode underway). Gilt = 75 (sovereign, liquid, but volatile). | C38: Set-and-forget except in stress | D38: Normal times → 90 / 65 / 75.
A39: PRECIOUS METALS SPLIT (Gold vs Silver)
A40: Signal | B40: Exact calculation — step by step | C40: Data source | D40: Worked example
A41: Gold/Silver ratio positioning | B41: Ratio %ile computes automatically in the metals log. Silver score = ratio %ile AS-IS (high ratio = silver cheap vs gold). Gold score = 100 − ratio %ile. | C41: Data Trackers metals log | D41: Ratio at 80th %ile of history → Silver 80, Gold 20.
A42: Real-rates trend benefit | B42: Same TIPS 6M-change rubric as L1 metals: falling >50bp → Gold 75, Silver 65. Falling 10–50bp → 60/57. Flat → 50/50. Rising → 40/45. (Gold is the purer real-rates asset.) | C42: FRED DFII10 | D42: TIPS −30bp → Gold 60, Silver 57.
...

Sheet L1 Asset Classes
A1: Level 1 — Asset Class Scoring & Tilt
A2: Attractiveness percentiles, 0–100, higher = more attractive forward. See Weights & Rules for per-class guidance.
A4: Signal | B4: Equity | C4: Debt | D4: Precious Metals | E4: Notes
A5: Valuation / carry attractiveness | B5: 45 | C5: 65 | D5: 35
A6: Macro / cycle support | B6: 55 | C6: 60 | D6: 60
A7: Fundamentals | B7: 55 | C7: 55 | D7: 65
A8: Flows & sentiment (contrarian) | B8: 40 | C8: 55 | D8: 30
A9: Momentum (12M relative) | B9: 60 | C9: 45 | D9: 75
A10: COMPOSITE | B10: =SUMPRODUCT('Weights & Rules'!$B$5:$B$9,B5:B9) -> 50.5 | C10: =SUMPRODUCT('Weights & Rules'!$B$5:$B$9,C5:C9) -> 57.5 | D10: =SUMPRODUCT('Weights & Rules'!$B$5:$B$9,D5:D9) -> 51.25
A11: VETO ACTIVE? (Y/N) | B11: N | C11: N | D11: N
A13: Asset class tilt
A14: Bucket | B14: Neutral Weight (within group) | C14: Composite Score | D14: Veto? | E14: Tilt (capped) | F14: Preliminary | G14: FINAL (normalized) | H14: vs Neutral
A15: Equity | B15: 0.55 | C15: =B10 -> 50.5 | D15: =B11 -> N | E15: =IF(D15="Y",MIN(0,MAX(-'Weights & Rules'!$B$46,MIN('Weights & Rules'!$B$46,(C15-50)/50*'Weights & Rules'!$B$46))),MAX(-'Weights & Rules'!$B$46,MIN('Weights & Rules'!$B$46,(C15-50)/50*'Weights & Rules'!$B$46))) -> 0.002 | F15: =B15*(1+E15) -> 0.5511 | G15: =F15/SUM($F$15:$F$17) -> 0.54451141 | H15: =G15-B15 -> -0.0054885881
A16: Debt | B16: 0.35 | C16: =C10 -> 57.5 | D16: =C11 -> N | E16: =IF(D16="Y",MIN(0,MAX(-'Weights & Rules'!$B$46,MIN('Weights & Rules'!$B$46,(C16-50)/50*'Weights & Rules'!$B$46))),MAX(-'Weights & Rules'!$B$46,MIN('Weights & Rules'!$B$46,(C16-50)/50*'Weights & Rules'!$B$46))) -> 0.03 | F16: =B16*(1+E16) -> 0.3605 | G16: =F16/SUM($F$15:$F$17) -> 0.3561901 | H16: =G16-B16 -> 0.0061900998
A17: Precious Metals | B17: 0.1 | C17: =D10 -> 51.25 | D17: =D11 -> N | E17: =IF(D17="Y",MIN(0,MAX(-'Weights & Rules'!$B$46,MIN('Weights & Rules'!$B$46,(C17-50)/50*'Weights & Rules'!$B$46))),MAX(-'Weights & Rules'!$B$46,MIN('Weights & Rules'!$B$46,(C17-50)/50*'Weights & Rules'!$B$46))) -> 0.005 | F17: =B17*(1+E17) -> 0.1005 | G17: =F17/SUM($F$15:$F$17) -> 0.099298488 | H17: =G17-B17 -> -0.00070151171
A18: Total | B18: =SUM(B15:B17) -> 1 | G18: =SUM(G15:G17) -> 1 | H18: =IF(ABS(B18-1)<0.001,"OK","Neutrals must sum to 100%") -> OK

Sheet Equity Segments
A1: Level 2 — Equity Segments (weights within equity)
A2: Same conventions. Neutral weights below are % of the EQUITY bucket, not of the portfolio.
A4: Signal | B4: Large Cap | C4: Mid Cap | D4: Small Cap | E4: International | F4: Notes
A5: Valuation vs own history | B5: 55 | C5: 35 | D5: 25 | E5: 40
A6: Relative value vs segments | B6: 60 | C6: 30 | D6: 20 | E6: 45
A7: Earnings revision breadth | B7: 50 | C7: 55 | D7: 45 | E7: 60
A8: Earnings growth differential | B8: 45 | C8: 60 | D8: 55 | E8: 65
A9: Margin / cycle position | B9: 55 | C9: 40 | D9: 30 | E9: 50
A10: COMPOSITE | B10: =SUMPRODUCT('Weights & Rules'!$B$14:$B$18,B5:B9) -> 53.5 | C10: =SUMPRODUCT('Weights & Rules'!$B$14:$B$18,C5:C9) -> 42.5 | D10: =SUMPRODUCT('Weights & Rules'!$B$14:$B$18,D5:D9) -> 33.25 | E10: =SUMPRODUCT('Weights & Rules'!$B$14:$B$18,E5:E9) -> 50.25
A11: VETO ACTIVE? (Y/N) | B11: N | C11: N | D11: Y | E11: N
A13: Segment tilt (within equity)
A14: Bucket | B14: Neutral Weight (within group) | C14: Composite Score | D14: Veto? | E14: Tilt (capped) | F14: Preliminary | G14: FINAL (normalized) | H14: vs Neutral
A15: Large Cap | B15: 0.45 | C15: =B10 -> 53.5 | D15: =B11 -> N | E15: =IF(D15="Y",MIN(0,MAX(-'Weights & Rules'!$B$47,MIN('Weights & Rules'!$B$47,(C15-50)/50*'Weights & Rules'!$B$47))),MAX(-'Weights & Rules'!$B$47,MIN('Weights & Rules'!$B$47,(C15-50)/50*'Weights & Rules'!$B$47))) -> 0.021 | F15: =B15*(1+E15) -> 0.45945 | G15: =F15/SUM($F$15:$F$18) -> 0.46612727 | H15: =G15-B15 -> 0.016127273
A16: Mid Cap | B16: 0.2 | C16: =C10 -> 42.5 | D16: =C11 -> N | E16: =IF(D16="Y",MIN(0,MAX(-'Weights & Rules'!$B$47,MIN('Weights & Rules'!$B$47,(C16-50)/50*'Weights & Rules'!$B$47))),MAX(-'Weights & Rules'!$B$47,MIN('Weights & Rules'!$B$47,(C16-50)/50*'Weights & Rules'!$B$47))) -> -0.045 | F16: =B16*(1+E16) -> 0.191 | G16: =F16/SUM($F$15:$F$18) -> 0.19377584 | H16: =G16-B16 -> -0.0062241611
A17: Small Cap | B17: 0.15 | C17: =D10 -> 33.25 | D17: =D11 -> Y | E17: =IF(D17="Y",MIN(0,MAX(-'Weights & Rules'!$B$47,MIN('Weights & Rules'!$B$47,(C17-50)/50*'Weights & Rules'!$B$47))),MAX(-'Weights & Rules'!$B$47,MIN('Weights & Rules'!$B$47,(C17-50)/50*'Weights & Rules'!$B$47))) -> -0.1005 | F17: =B17*(1+E17) -> 0.134925 | G17: =F17/SUM($F$15:$F$18) -> 0.13688589 | H17: =G17-B17 -> -0.01311411
A18: International | B18: 0.2 | C18: =E10 -> 50.25 | D18: =E11 -> N | E18: =IF(D18="Y",MIN(0,MAX(-'Weights & Rules'!$B$47,MIN('Weights & Rules'!$B$47,(C18-50)/50*'Weights & Rules'!$B$47))),MAX(-'Weights & Rules'!$B$47,MIN('Weights & Rules'!$B$47,(C18-50)/50*'Weights & Rules'!$B$47))) -> 0.0015 | F18: =B18*(1+E18) -> 0.2003 | G18: =F18/SUM($F$15:$F$18) -> 0.203211 | H18: =G18-B18 -> 0.0032109975
A19: Total | B19: =SUM(B15:B18) -> 1 | G19: =SUM(G15:G18) -> 1 | H19: =IF(ABS(B19-1)<0.001,"OK","Neutrals must sum to 100%") -> OK

Sheet Debt Buckets
A1: Level 2 — Debt Buckets (weights within debt)
A2: Buckets by duration/credit role. Yield percentiles NOT inverted: high yield vs history = attractive carry.
A4: Signal | B4: Liquid / Short | C4: Corporate / Medium | D4: Gilt / Long | E4: Notes
A5: Carry vs history (YTM %ile) | B5: 55 | C5: 60 | D5: 65
A6: Rate-cycle duration benefit | B6: 40 | C6: 55 | D6: 70
A7: Credit spread cushion | B7: 50 | C7: 45 | D7: 50
A8: Liquidity / redemption safety | B8: 90 | C8: 65 | D8: 75
A9: COMPOSITE | B9: =SUMPRODUCT('Weights & Rules'!$B$23:$B$26,B5:B8) -> 54.5 | C9: =SUMPRODUCT('Weights & Rules'!$B$23:$B$26,C5:C8) -> 55.5 | D9: =SUMPRODUCT('Weights & Rules'!$B$23:$B$26,D5:D8) -> 64.25
A10: VETO ACTIVE? (Y/N) | B10: N | C10: N | D10: N
A12: Bucket tilt (within debt)
A13: Bucket | B13: Neutral Weight (within group) | C13: Composite Score | D13: Veto? | E13: Tilt (capped) | F13: Preliminary | G13: FINAL (normalized) | H13: vs Neutral
A14: Liquid / Short | B14: 0.4 | C14: =B9 -> 54.5 | D14: =B10 -> N | E14: =IF(D14="Y",MIN(0,MAX(-'Weights & Rules'!$B$48,MIN('Weights & Rules'!$B$48,(C14-50)/50*'Weights & Rules'!$B$48))),MAX(-'Weights & Rules'!$B$48,MIN('Weights & Rules'!$B$48,(C14-50)/50*'Weights & Rules'!$B$48))) -> 0.027 | F14: =B14*(1+E14) -> 0.4108 | G14: =F14/SUM($F$14:$F$16) -> 0.39359027 | H14: =G14-B14 -> -0.0064097344
A15: Corporate / Medium | B15: 0.35 | C15: =C9 -> 55.5 | D15: =C10 -> N | E15: =IF(D15="Y",MIN(0,MAX(-'Weights & Rules'!$B$48,MIN('Weights & Rules'!$B$48,(C15-50)/50*'Weights & Rules'!$B$48))),MAX(-'Weights & Rules'!$B$48,MIN('Weights & Rules'!$B$48,(C15-50)/50*'Weights & Rules'!$B$48))) -> 0.033 | F15: =B15*(1+E15) -> 0.36155 | G15: =F15/SUM($F$14:$F$16) -> 0.34640351 | H15: =G15-B15 -> -0.0035964933
A16: Gilt / Long | B16: 0.25 | C16: =D9 -> 64.25 | D16: =D10 -> N | E16: =IF(D16="Y",MIN(0,MAX(-'Weights & Rules'!$B$48,MIN('Weights & Rules'!$B$48,(C16-50)/50*'Weights & Rules'!$B$48))),MAX(-'Weights & Rules'!$B$48,MIN('Weights & Rules'!$B$48,(C16-50)/50*'Weights & Rules'!$B$48))) -> 0.0855 | F16: =B16*(1+E16) -> 0.271375 | G16: =F16/SUM($F$14:$F$16) -> 0.26000623 | H16: =G16-B16 -> 0.010006228
A17: Total | B17: =SUM(B14:B16) -> 1 | G17: =SUM(G14:G16) -> 1 | H17: =IF(ABS(B17-1)<0.001,"OK","Neutrals must sum to 100%") -> OK

Sheet Precious Metals
A1: Level 2 — Gold vs Silver split
A2: Ratio logic: very high gold/silver ratio = silver historically cheap vs gold. Gold scores neutral (50) on industrial demand.
A4: Signal | B4: Gold | C4: Silver | D4: Notes
A5: Gold/Silver ratio positioning | B5: 40 | C5: 60
A6: Real-rates trend benefit | B6: 65 | C6: 55
A7: Industrial demand cycle | B7: 50 | C7: 55
A8: COMPOSITE | B8: =SUMPRODUCT('Weights & Rules'!$B$31:$B$33,B5:B7) -> 51.25 | C8: =SUMPRODUCT('Weights & Rules'!$B$31:$B$33,C5:C7) -> 57
A9: VETO ACTIVE? (Y/N) | B9: N | C9: N
A11: Metal tilt (within precious metals)
A12: Bucket | B12: Neutral Weight (within group) | C12: Composite Score | D12: Veto? | E12: Tilt (capped) | F12: Preliminary | G12: FINAL (normalized) | H12: vs Neutral
A13: Gold | B13: 0.75 | C13: =B8 -> 51.25 | D13: =B9 -> N | E13: =IF(D13="Y",MIN(0,MAX(-'Weights & Rules'!$B$49,MIN('Weights & Rules'!$B$49,(C13-50)/50*'Weights & Rules'!$B$49))),MAX(-'Weights & Rules'!$B$49,MIN('Weights & Rules'!$B$49,(C13-50)/50*'Weights & Rules'!$B$49))) -> 0.00625 | F13: =B13*(1+E13) -> 0.7546875 | G13: =F13/SUM($F$13:$F$14) -> 0.74468085 | H13: =G13-B13 -> -0.0053191489
A14: Silver | B14: 0.25 | C14: =C8 -> 57 | D14: =C9 -> N | E14: =IF(D14="Y",MIN(0,MAX(-'Weights & Rules'!$B$49,MIN('Weights & Rules'!$B$49,(C14-50)/50*'Weights & Rules'!$B$49))),MAX(-'Weights & Rules'!$B$49,MIN('Weights & Rules'!$B$49,(C14-50)/50*'Weights & Rules'!$B$49))) -> 0.035 | F14: =B14*(1+E14) -> 0.25875 | G14: =F14/SUM($F$13:$F$14) -> 0.25531915 | H14: =G14-B14 -> 0.0053191489
A15: Total | B15: =SUM(B13:B14) -> 1 | G15: =SUM(G13:G14) -> 1 | H15: =IF(ABS(B15-1)<0.001,"OK","Neutrals must sum to 100%") -> OK

Sheet Sector Satellite
A1: Sector Satellite (caged sleeve within equity)
A2: Sectors must clear the qualification threshold to enter at all — the sleeve's default state is EMPTY. Max sectors and sleeve cap set on Weights & Rules.
A4: Sector | B4: Valuation vs History | C4: Earnings Revisions | D4: Rel. Momentum | E4: Cycle Position | F4: Composite | G4: Veto? (Y/N) | H4: Qualifies?
A5: Banking / Financials | B5: 60 | C5: 55 | D5: 50 | E5: 55 | F5: 55.25 | G5: N | H5: =IF($A5="","",IF(G5="Y","VETOED",IF(F5>='Weights & Rules'!$B$52,"QUALIFIES","No"))) -> No
A6: IT Services | B6: 55 | C6: 40 | D6: 35 | E6: 45 | F6: 44 | G6: N | H6: =IF($A6="","",IF(G6="Y","VETOED",IF(F6>='Weights & Rules'!$B$52,"QUALIFIES","No"))) -> No
A7: Pharma / Healthcare | B7: 50 | C7: 65 | D7: 60 | E7: 55 | F7: 57.75 | G7: N | H7: =IF($A7="","",IF(G7="Y","VETOED",IF(F7>='Weights & Rules'!$B$52,"QUALIFIES","No"))) -> No
A8: Auto | B8: 45 | C8: 55 | D8: 55 | E8: 60 | F8: 52.75 | G8: N | H8: =IF($A8="","",IF(G8="Y","VETOED",IF(F8>='Weights & Rules'!$B$52,"QUALIFIES","No"))) -> No
A9: Capital Goods / Infra | B9: 60 | C9: 75 | D9: 80 | E9: 70 | F9: 71 | G9: N | H9: =IF($A9="","",IF(G9="Y","VETOED",IF(F9>='Weights & Rules'!$B$52,"QUALIFIES","No"))) -> QUALIFIES
A10: FMCG / Consumer | B10: 55 | C10: 45 | D10: 40 | E10: 50 | F10: 47.5 | G10: N | H10: =IF($A10="","",IF(G10="Y","VETOED",IF(F10>='Weights & Rules'!$B$52,"QUALIFIES","No"))) -> No
A11: Energy / Commodities | B11: 60 | C11: 50 | D11: 45 | E11: 40 | F11: 50.25 | G11: N | H11: =IF($A11="","",IF(G11="Y","VETOED",IF(F11>='Weights & Rules'!$B$52,"QUALIFIES","No"))) -> No
A12: Metals | B12: 55 | C12: 45 | D12: 50 | E12: 35 | F12: 47.75 | G12: N | H12: =IF($A12="","",IF(G12="Y","VETOED",IF(F12>='Weights & Rules'!$B$52,"QUALIFIES","No"))) -> No
A14: Qualifying sectors (count) | B14: =COUNTIF(H5:H12,"QUALIFIES") -> 1 | C14: =IF(B14>'Weights & Rules'!$B$51,"Take only the top-scoring "&'Weights & Rules'!$B$51&" — max sectors rule","")
A16: Rule: if more sectors qualify than the max, hold only the highest-composite ones. Deployed sleeve = sleeve cap × (sectors held ÷ max sectors), split equally. Enter the chosen sectors on Portfolio Rollup.

Sheet Portfolio Rollup
A1: Portfolio Rollup — Final Allocation
A2: All levels multiplied through. Sector sleeve is carved out of equity; core equity segments scale down proportionally when the sleeve deploys.
A4: Control | B4: Value | C4: Notes
A5: Sectors held (0, 1 or 2) | B5: 1 | C5: Must not exceed qualifying count on Sector Satellite, nor the max sectors rule.
A6: Deployed sleeve (% of equity) | B6: =$B$5/'Weights & Rules'!$B$51*'Weights & Rules'!$B$50 -> 0.075 | C6: Sleeve cap × sectors held ÷ max sectors; equal split per sector.
A8: Line Item | B8: Group Weight | C8: Weight Within Group | D8: PORTFOLIO WEIGHT | E8: Notes
A9: Large Cap (core equity) | B9: ='L1 Asset Classes'!$G$15 -> 0.54451141 | C9: ='Equity Segments'!$G$15*(1-$B$6) -> 0.43116773 | D9: =B9*C9 -> 0.23477575
A10: Mid Cap (core equity) | B10: ='L1 Asset Classes'!$G$15 -> 0.54451141 | C10: ='Equity Segments'!$G$16*(1-$B$6) -> 0.17924265 | D10: =B10*C10 -> 0.097599669
A11: Small Cap (core equity) | B11: ='L1 Asset Classes'!$G$15 -> 0.54451141 | C11: ='Equity Segments'!$G$17*(1-$B$6) -> 0.12661945 | D11: =B11*C11 -> 0.068945735
A12: International (core equity) | B12: ='L1 Asset Classes'!$G$15 -> 0.54451141 | C12: ='Equity Segments'!$G$18*(1-$B$6) -> 0.18797017 | D12: =B12*C12 -> 0.1023519
A13: Sector sleeve — Capital Goods / Infra (sample) | B13: ='L1 Asset Classes'!$G$15 -> 0.54451141 | C13: =IF($B$5>=1,$B$6/MAX(1,$B$5),0) -> 0.075 | D13: =B13*C13 -> 0.040838356
A14: Sector sleeve — Sector 2 [name] | B14: ='L1 Asset Classes'!$G$15 -> 0.54451141 | C14: =IF($B$5>=2,$B$6/MAX(1,$B$5),0) -> 0 | D14: =B14*C14 -> 0
A15: Liquid / Short (debt) | B15: ='L1 Asset Classes'!$G$16 -> 0.3561901 | C15: ='Debt Buckets'!$G$14 -> 0.39359027 | D15: =B15*C15 -> 0.14019296
A16: Corporate / Medium (debt) | B16: ='L1 Asset Classes'!$G$16 -> 0.3561901 | C16: ='Debt Buckets'!$G$15 -> 0.34640351 | D16: =B16*C16 -> 0.1233855
A17: Gilt / Long (debt) | B17: ='L1 Asset Classes'!$G$16 -> 0.3561901 | C17: ='Debt Buckets'!$G$16 -> 0.26000623 | D17: =B17*C17 -> 0.092611644
A18: Gold | B18: ='L1 Asset Classes'!$G$17 -> 0.099298488 | C18: ='Precious Metals'!$G$13 -> 0.74468085 | D18: =B18*C18 -> 0.073945683
A19: Silver | B19: ='L1 Asset Classes'!$G$17 -> 0.099298488 | C19: ='Precious Metals'!$G$14 -> 0.25531915 | D19: =B19*C19 -> 0.025352806
A20: TOTAL | D20: =SUM(D9:D19) -> 1 | E20: =IF(ABS(D20-1)<0.001,"OK","Must equal 100% — check inputs") -> OK
A22: Name the chosen sectors in the sleeve rows (from Sector Satellite qualifiers, highest composite first). If no sector qualifies, set sectors held = 0 and the sleeve returns to core equity automatically.

Sheet Data Trackers
A1: Data Trackers
A2: Log monthly. Percentiles build automatically; seed with history where possible (~24+ rows for meaning). High spread/valuation percentile = expensive = LOW attractiveness when scoring; high YIELD percentile = attractive carry (no inversion).
A4: Equity valuation log (index P/E, niftyindices.com)
A5: Month | B5: Nifty 100 P/E | C5: Midcap 150 P/E | D5: Smallcap 250 P/E | E5: Mid–Large Spread | F5: Small–Large Spread | G5: Mid Spread %ile | H5: Small Spread %ile
A6: Jan-2026 | B6: 22.5 | C6: 33.1 | D6: 30.2 | E6: =IF($B6="","",C6-B6) -> 10.6 | F6: =IF($B6="","",D6-B6) -> 7.7 | G6: =IF($B6="","",IFERROR(PERCENTRANK($E$6:$E$53,E6)*100,"")) -> 100 | H6: =IF($B6="","",IFERROR(PERCENTRANK($F$6:$F$53,F6)*100,"")) -> 100
A7: Feb-2026 | B7: 21.8 | C7: 31.9 | D7: 28.8 | E7: =IF($B7="","",C7-B7) -> 10.1 | F7: =IF($B7="","",D7-B7) -> 7 | G7: =IF($B7="","",IFERROR(PERCENTRANK($E$6:$E$53,E7)*100,"")) -> 0 | H7: =IF($B7="","",IFERROR(PERCENTRANK($F$6:$F$53,F7)*100,"")) -> 0
A8: Mar-2026 | B8: 22.1 | C8: 32.4 | D8: 29.5 | E8: =IF($B8="","",C8-B8) -> 10.3 | F8: =IF($B8="","",D8-B8) -> 7.4 | G8: =IF($B8="","",IFERROR(PERCENTRANK($E$6:$E$53,E8)*100,"")) -> 50 | H8: =IF($B8="","",IFERROR(PERCENTRANK($F$6:$F$53,F8)*100,"")) -> 50
E9: =IF($B9="","",C9-B9) | F9: =IF($B9="","",D9-B9) | G9: =IF($B9="","",IFERROR(PERCENTRANK($E$6:$E$53,E9)*100,"")) | H9: =IF($B9="","",IFERROR(PERCENTRANK($F$6:$F$53,F9)*100,""))
E10: =IF($B10="","",C10-B10) | F10: =IF($B10="","",D10-B10) | G10: =IF($B10="","",IFERROR(PERCENTRANK($E$6:$E$53,E10)*100,"")) | H10: =IF($B10="","",IFERROR(PERCENTRANK($F$6:$F$53,F10)*100,""))
E11: =IF($B11="","",C11-B11) | F11: =IF($B11="","",D11-B11) | G11: =IF($B11="","",IFERROR(PERCENTRANK($E$6:$E$53,E11)*100,"")) | H11: =IF($B11="","",IFERROR(PERCENTRANK($F$6:$F$53,F11)*100,""))
E12: =IF($B12="","",C12-B12) | F12: =IF($B12="","",D12-B12) | G12: =IF($B12="","",IFERROR(PERCENTRANK($E$6:$E$53,E12)*100,"")) | H12: =IF($B12="","",IFERROR(PERCENTRANK($F$6:$F$53,F12)*100,""))
E13: =IF($B13="","",C13-B13) | F13: =IF($B13="","",D13-B13) | G13: =IF($B13="","",IFERROR(PERCENTRANK($E$6:$E$53,E13)*100,"")) | H13: =IF($B13="","",IFERROR(PERCENTRANK($F$6:$F$53,F13)*100,""))
E14: =IF($B14="","",C14-B14) | F14: =IF($B14="","",D14-B14) | G14: =IF($B14="","",IFERROR(PERCENTRANK($E$6:$E$53,E14)*100,"")) | H14: =IF($B14="","",IFERROR(PERCENTRANK($F$6:$F$53,F14)*100,""))
E15: =IF($B15="","",C15-B15) | F15: =IF($B15="","",D15-B15) | G15: =IF($B15="","",IFERROR(PERCENTRANK($E$6:$E$53,E15)*100,"")) | H15: =IF($B15="","",IFERROR(PERCENTRANK($F$6:$F$53,F15)*100,""))
E16: =IF($B16="","",C16-B16) | F16: =IF($B16="","",D16-B16) | G16: =IF($B16="","",IFERROR(PERCENTRANK($E$6:$E$53,E16)*100,"")) | H16: =IF($B16="","",IFERROR(PERCENTRANK($F$6:$F$53,F16)*100,""))
E17: =IF($B17="","",C17-B17) | F17: =IF($B17="","",D17-B17) | G17: =IF($B17="","",IFERROR(PERCENTRANK($E$6:$E$53,E17)*100,"")) | H17: =IF($B17="","",IFERROR(PERCENTRANK($F$6:$F$53,F17)*100,""))
E18: =IF($B18="","",C18-B18) | F18: =IF($B18="","",D18-B18) | G18: =IF($B18="","",IFERROR(PERCENTRANK($E$6:$E$53,E18)*100,"")) | H18: =IF($B18="","",IFERROR(PERCENTRANK($F$6:$F$53,F18)*100,""))
E19: =IF($B19="","",C19-B19) | F19: =IF($B19="","",D19-B19) | G19: =IF($B19="","",IFERROR(PERCENTRANK($E$6:$E$53,E19)*100,"")) | H19: =IF($B19="","",IFERROR(PERCENTRANK($F$6:$F$53,F19)*100,""))
E20: =IF($B20="","",C20-B20) | F20: =IF($B20="","",D20-B20) | G20: =IF($B20="","",IFERROR(PERCENTRANK($E$6:$E$53,E20)*100,"")) | H20: =IF($B20="","",IFERROR(PERCENTRANK($F$6:$F$53,F20)*100,""))
... E53: =IF($B53="","",C53-B53) | F53: =IF($B53="","",D53-B53) | G53: =IF($B53="","",IFERROR(PERCENTRANK($E$6:$E$53,E53)*100,"")) | H53: =IF($B53="","",IFERROR(PERCENTRANK($F$6:$F$53,F53)*100,""))
A55: Rates & credit log (RBI/CCIL, FIMMDA or broker reports)
A56: Month | B56: 10Y G-sec Yield % | C56: Repo Rate % | D56: 3Y AAA Corp Yield % | E56: AAA Spread (bps) | F56: 10Y Yield %ile | G56: Spread %ile
A57: Jan-2026 | B57: 6.75 | C57: 6 | D57: 7.4 | E57: =IF($B57="","",(D57-B57)*100) -> 65 | F57: =IF($B57="","",IFERROR(PERCENTRANK($B$57:$B$104,B57)*100,"")) -> 100 | G57: =IF($B57="","",IFERROR(PERCENTRANK($E$57:$E$104,E57)*100,"")) -> 50
A58: Feb-2026 | B58: 6.68 | C58: 6 | D58: 7.3 | E58: =IF($B58="","",(D58-B58)*100) -> 62 | F58: =IF($B58="","",IFERROR(PERCENTRANK($B$57:$B$104,B58)*100,"")) -> 0 | G58: =IF($B58="","",IFERROR(PERCENTRANK($E$57:$E$104,E58)*100,"")) -> 0
A59: Mar-2026 | B59: 6.72 | C59: 5.75 | D59: 7.38 | E59: =IF($B59="","",(D59-B59)*100) -> 66 | F59: =IF($B59="","",IFERROR(PERCENTRANK($B$57:$B$104,B59)*100,"")) -> 50 | G59: =IF($B59="","",IFERROR(PERCENTRANK($E$57:$E$104,E59)*100,"")) -> 100
E60: =IF($B60="","",(D60-B60)*100) | F60: =IF($B60="","",IFERROR(PERCENTRANK($B$57:$B$104,B60)*100,"")) | G60: =IF($B60="","",IFERROR(PERCENTRANK($E$57:$E$104,E60)*100,""))
E61: =IF($B61="","",(D61-B61)*100) | F61: =IF($B61="","",IFERROR(PERCENTRANK($B$57:$B$104,B61)*100,"")) | G61: =IF($B61="","",IFERROR(PERCENTRANK($E$57:$E$104,E61)*100,""))
E62: =IF($B62="","",(D62-B62)*100) | F62: =IF($B62="","",IFERROR(PERCENTRANK($B$57:$B$104,B62)*100,"")) | G62: =IF($B62="","",IFERROR(PERCENTRANK($E$57:$E$104,E62)*100,""))
E63: =IF($B63="","",(D63-B63)*100) | F63: =IF($B63="","",IFERROR(PERCENTRANK($B$57:$B$104,B63)*100,"")) | G63: =IF($B63="","",IFERROR(PERCENTRANK($E$57:$E$104,E63)*100,""))
E64: =IF($B64="","",(D64-B64)*100) | F64: =IF($B64="","",IFERROR(PERCENTRANK($B$57:$B$104,B64)*100,"")) | G64: =IF($B64="","",IFERROR(PERCENTRANK($E$57:$E$104,E64)*100,""))
E65: =IF($B65="","",(D65-B65)*100) | F65: =IF($B65="","",IFERROR(PERCENTRANK($B$57:$B$104,B65)*100,"")) | G65: =IF($B65="","",IFERROR(PERCENTRANK($E$57:$E$104,E65)*100,""))
E66: =IF($B66="","",(D66-B66)*100) | F66: =IF($B66="","",IFERROR(PERCENTRANK($B$57:$B$104,B66)*100,"")) | G66: =IF($B66="","",IFERROR(PERCENTRANK($E$57:$E$104,E66)*100,""))
E67: =IF($B67="","",(D67-B67)*100) | F67: =IF($B67="","",IFERROR(PERCENTRANK($B$57:$B$104,B67)*100,"")) | G67: =IF($B67="","",IFERROR(PERCENTRANK($E$57:$E$104,E67)*100,""))
E68: =IF($B68="","",(D68-B68)*100) | F68: =IF($B68="","",IFERROR(PERCENTRANK($B$57:$B$104,B68)*100,"")) | G68: =IF($B68="","",IFERROR(PERCENTRANK($E$57:$E$104,E68)*100,""))
E69: =IF($B69="","",(D69-B69)*100) | F69: =IF($B69="","",IFERROR(PERCENTRANK($B$57:$B$104,B69)*100,"")) | G69: =IF($B69="","",IFERROR(PERCENTRANK($E$57:$E$104,E69)*100,""))
E70: =IF($B70="","",(D70-B70)*100) | F70: =IF($B70="","",IFERROR(PERCENTRANK($B$57:$B$104,B70)*100,"")) | G70: =IF($B70="","",IFERROR(PERCENTRANK($E$57:$E$104,E70)*100,""))
E71: =IF($B71="","",(D71-B71)*100) | F71: =IF($B71="","",IFERROR(PERCENTRANK($B$57:$B$104,B71)*100,"")) | G71: =IF($B71="","",IFERROR(PERCENTRANK($E$57:$E$104,E71)*100,""))
... E104: =IF($B104="","",(D104-B104)*100) | F104: =IF($B104="","",IFERROR(PERCENTRANK($B$57:$B$104,B104)*100,"")) | G104: =IF($B104="","",IFERROR(PERCENTRANK($E$57:$E$104,E104)*100,""))
A106: Precious metals log
A107: Month | B107: Gold ₹/10g | C107: Silver ₹/kg | D107: Gold/Silver Ratio | E107: Gold 12M Return % | F107: Ratio %ile | G107: Gold Ret %ile
...

Sheet Monitoring & Review
A1: Monitoring & Review
A3: Cadence
A4: Activity | B4: Frequency | C4: Notes
A5: Log all four Data Tracker tables | B5: Monthly | C5: ~15 minutes; the percentile history is the asset
A6: Veto gate check (all sheets) | B6: Monthly | C6: Flow extremes, AMC restrictions, parabolic metal moves can trigger between reviews
A7: Fast review: sector satellite + flows/momentum inputs | B7: Quarterly | C7: Sectors rotate faster than asset classes
A8: Full strategic re-score: L1 + all L2 sheets | B8: Semi-annual | C8: Implement tilt changes over 4–8 weeks
A9: Backtest & weight sensitivity vs historical MF data | B9: Annual | C9: Do the tilts flip with ±10% weight changes? Fragile = simplify
A10: Neutral weight / policy review | B10: Annual | C10: Risk-profile driven only — never framework-driven
A12: Standing rules
A13: Rule | B13: Action | C13: Rationale
A14: No tilt changes between reviews on news/price alone | B14: Wait for review or veto trigger | C14: The framework exists to prevent lurching
A15: Vetoes block overweights, never force underweights | B15: Cap at zero | C15: Risk gates, not signals
A16: Sector sleeve empties by default | B16: Sectors exit when composite falls below threshold at a quarterly review | C16: Sector timing has the worst base rates in this workbook — the cage matters more than the picks
A17: A sector exits after 4 consecutive quarters in the sleeve regardless of score | B17: Rotate out or re-underwrite from scratch | C17: Prevents satellite positions ossifying into permanent holdings
A18: Precious metals sleeve is a diversifier, not a bet | B18: Neutral ± tilt only; never >2× neutral | C18: Gold's job is crisis correlation, not returns
A19: Extreme scores (>80 / <20) for two consecutive reviews | B19: Allow full-cap tilt | C19: Extremes are where the framework earns its keep
